[2025-10-26 16:21:23] ERROR [telegram.ext.Application.process_error:1917] No error handlers are registered, logging exception.
Traceback (most recent call last):
  File "C:\Projekte\Halloween25\.venv\Lib\site-packages\telegram\ext\_updater.py", line 753, in _network_loop_retry
    if not await do_action():
           ^^^^^^^^^^^^^^^^^
  File "C:\Projekte\Halloween25\.venv\Lib\site-packages\telegram\ext\_updater.py", line 747, in do_action
    return action_cb_task.result()
           ^^^^^^^^^^^^^^^^^^^^^^^
  File "C:\Projekte\Halloween25\.venv\Lib\site-packages\telegram\ext\_updater.py", line 377, in polling_action_cb
    updates = await self.bot.get_updates(
              ^^^^^^^^^^^^^^^^^^^^^^^^^^^
  File "C:\Projekte\Halloween25\.venv\Lib\site-packages\telegram\ext\_extbot.py", line 649, in get_updates
    updates = await super().get_updates(
              ^^^^^^^^^^^^^^^^^^^^^^^^^^
  File "C:\Projekte\Halloween25\.venv\Lib\site-packages\telegram\_bot.py", line 4366, in get_updates
    await self._post(
  File "C:\Projekte\Halloween25\.venv\Lib\site-packages\telegram\_bot.py", line 623, in _post
    return await self._do_post(
           ^^^^^^^^^^^^^^^^^^^^
  File "C:\Projekte\Halloween25\.venv\Lib\site-packages\telegram\ext\_extbot.py", line 355, in _do_post
    return await super()._do_post(
           ^^^^^^^^^^^^^^^^^^^^^^^
  File "C:\Projekte\Halloween25\.venv\Lib\site-packages\telegram\_bot.py", line 652, in _do_post
    result = await request.post(
             ^^^^^^^^^^^^^^^^^^^
  File "C:\Projekte\Halloween25\.venv\Lib\site-packages\telegram\request\_baserequest.py", line 201, in post
    result = await self._request_wrapper(
             ^^^^^^^^^^^^^^^^^^^^^^^^^^^^
  File "C:\Projekte\Halloween25\.venv\Lib\site-packages\telegram\request\_baserequest.py", line 384, in _request_wrapper
    raise Conflict(message)
telegram.error.Conflict: Conflict: terminated by other getUpdates request; make sure that only one bot instance is running
[2025-10-26 16:21:29] ERROR [telegram.ext.Application.process_error:1917] No error handlers are registered, logging exception.
Traceback (most recent call last):
  File "C:\Projekte\Halloween25\.venv\Lib\site-packages\telegram\ext\_updater.py", line 753, in _network_loop_retry
    if not await do_action():
           ^^^^^^^^^^^^^^^^^
  File "C:\Projekte\Halloween25\.venv\Lib\site-packages\telegram\ext\_updater.py", line 747, in do_action
    return action_cb_task.result()
           ^^^^^^^^^^^^^^^^^^^^^^^
  File "C:\Projekte\Halloween25\.venv\Lib\site-packages\telegram\ext\_updater.py", line 377, in polling_action_cb
    updates = await self.bot.get_updates(
              ^^^^^^^^^^^^^^^^^^^^^^^^^^^
  File "C:\Projekte\Halloween25\.venv\Lib\site-packages\telegram\ext\_extbot.py", line 649, in get_updates
    updates = await super().get_updates(
              ^^^^^^^^^^^^^^^^^^^^^^^^^^
  File "C:\Projekte\Halloween25\.venv\Lib\site-packages\telegram\_bot.py", line 4366, in get_updates
    await self._post(
  File "C:\Projekte\Halloween25\.venv\Lib\site-packages\telegram\_bot.py", line 623, in _post
    return await self._do_post(
           ^^^^^^^^^^^^^^^^^^^^
  File "C:\Projekte\Halloween25\.venv\Lib\site-packages\telegram\ext\_extbot.py", line 355, in _do_post
    return await super()._do_post(
           ^^^^^^^^^^^^^^^^^^^^^^^
  File "C:\Projekte\Halloween25\.venv\Lib\site-packages\telegram\_bot.py", line 652, in _do_post
    result = await request.post(
             ^^^^^^^^^^^^^^^^^^^
  File "C:\Projekte\Halloween25\.venv\Lib\site-packages\telegram\request\_baserequest.py", line 201, in post
    result = await self._request_wrapper(
             ^^^^^^^^^^^^^^^^^^^^^^^^^^^^
  File "C:\Projekte\Halloween25\.venv\Lib\site-packages\telegram\request\_baserequest.py", line 384, in _request_wrapper
    raise Conflict(message)
telegram.error.Conflict: Conflict: terminated by other getUpdates request; make sure that only one bot instance is running
[2025-10-26 16:21:36] ERROR [telegram.ext.Application.process_error:1917] No error handlers are registered, logging exception.
Traceback (most recent call last):
  File "C:\Projekte\Halloween25\.venv\Lib\site-packages\telegram\ext\_updater.py", line 753, in _network_loop_retry
    if not await do_action():
           ^^^^^^^^^^^^^^^^^
  File "C:\Projekte\Halloween25\.venv\Lib\site-packages\telegram\ext\_updater.py", line 747, in do_action
    return action_cb_task.result()
           ^^^^^^^^^^^^^^^^^^^^^^^
  File "C:\Projekte\Halloween25\.venv\Lib\site-packages\telegram\ext\_updater.py", line 377, in polling_action_cb
    updates = await self.bot.get_updates(
              ^^^^^^^^^^^^^^^^^^^^^^^^^^^
  File "C:\Projekte\Halloween25\.venv\Lib\site-packages\telegram\ext\_extbot.py", line 649, in get_updates
    updates = await super().get_updates(
              ^^^^^^^^^^^^^^^^^^^^^^^^^^
  File "C:\Projekte\Halloween25\.venv\Lib\site-packages\telegram\_bot.py", line 4366, in get_updates
    await self._post(
  File "C:\Projekte\Halloween25\.venv\Lib\site-packages\telegram\_bot.py", line 623, in _post
    return await self._do_post(
           ^^^^^^^^^^^^^^^^^^^^
  File "C:\Projekte\Halloween25\.venv\Lib\site-packages\telegram\ext\_extbot.py", line 355, in _do_post
    return await super()._do_post(
           ^^^^^^^^^^^^^^^^^^^^^^^
  File "C:\Projekte\Halloween25\.venv\Lib\site-packages\telegram\_bot.py", line 652, in _do_post
    result = await request.post(
             ^^^^^^^^^^^^^^^^^^^
  File "C:\Projekte\Halloween25\.venv\Lib\site-packages\telegram\request\_baserequest.py", line 201, in post
    result = await self._request_wrapper(
             ^^^^^^^^^^^^^^^^^^^^^^^^^^^^
  File "C:\Projekte\Halloween25\.venv\Lib\site-packages\telegram\request\_baserequest.py", line 384, in _request_wrapper
    raise Conflict(message)
telegram.error.Conflict: Conflict: terminated by other getUpdates request; make sure that only one bot instance is running
